Workbook

Sheet EXPECTED RESULTS
D8: SEMESTER-1 | J8: =I18/G18 -> 14.01875
D11: COURSE NAME | G11: CREDITS | H11: GRADE /20 | I11: CREDITS * GRADE
D12: APPLIED MATHEMATICS | G12: 3 | H12: 12 | I12: =G12*H12 -> 36
D13: INTRODUCTION TO BIBLE STUDIES | G13: 2 | H13: 15 | I13: =G13*H13 -> 30
D14: INTRODUCTION TO COMPUTER APPLICATION | G14: 3 | H14: 14 | I14: =G14*H14 -> 42
D15: PRINCIPALS OF ACCOUNTING | G15: 3 | H15: 14.9 | I15: =G15*H15 -> 44.7
D16: GENERAL ENGLISH | G16: 3 | H16: 14 | I16: =G16*H16 -> 42
D17: STUDY AND RESEARCH METHODS | G17: 2 | H17: 14.8 | I17: =G17*H17 -> 29.6
D18: TOTAL | G18: =SUM(G12:G17) -> 16 | I18: =SUM(I12:I17) -> 224.3
D19: ='FINAL RESULT'!D19 -> SEMESTER-2-SUMMER | J19: =I27/G27 -> 16.5
D23: COURSE NAME | G23: CREDITS | H23: GRADE /20 | I23: CREDITS * GRADE
D24: DBMS | G24: 3 | H24: 17 | I24: =G24*H24 -> 51
D25: Computer Maintenance | G25: 3 | H25: 16.5 | I25: =G25*H25 -> 49.5
D26: Digital computer Fundamentals | G26: 3 | H26: 16 | I26: =G26*H26 -> 48
D27: TOTAL | G27: =SUM(G24:G26) -> 9 | I27: =SUM(I24:I26) -> 148.5
D28: SEMESTER-3 | J28: =I38/G38 -> 16.144444
D32: COURSE NAME | G32: CREDITS | H32: GRADE /20 | I32: CREDITS * GRADE
D33: Multvaliable Calculus and ODE | G33: 4 | H33: 15 | I33: =G33*H33 -> 60
D34: Intro to Computer Programming | G34: 4 | H34: 16.8 | I34: =G34*H34 -> 67.2
D35: Software Engineering | G35: 3 | H35: 15.8 | I35: =G35*H35 -> 47.4
D36: Descrptive Statistics | G36: 3 | H36: 16 | I36: =G36*H36 -> 48
D37: Computer Networks | G37: 4 | H37: 17 | I37: =G37*H37 -> 68
D38: TOTAL | G38: =SUM(G33:G37) -> 18 | I38: =SUM(I33:I37) -> 290.6
J39: =I48/G48 -> 16.026316
D41: COURSE NAME | G41: CREDITS | H41: GRADE /20 | I41: CREDITS * GRADE
D42: Operating systems | G42: 4 | H42: 15.5 | I42: =G42*H42 -> 62
D43: Academic English Writing | G43: 3 | H43: 16 | I43: =G43*H43 -> 48
D44: Programming with C | G44: 4 | H44: 17 | I44: =G44*H44 -> 68
D45: Probalibility and Statistics | G45: 3 | H45: 16 | I45: =G45*H45 -> 48
D46: Software Project management | G46: 3 | H46: 15.5 | I46: =G46*H46 -> 46.5
D47: Healph Principles | G47: 2 | H47: 16 | I47: =G47*H47 -> 32
D48: TOTAL | G48: =SUM(G42:G47) -> 19 | I48: =SUM(I42:I47) -> 304.5
D49: SEMESTER-5-SUMMER | J49: =I57/G57 -> 17.166667
D53: COURSE NAME | G53: CREDITS | H53: GRADE /20 | I53: CREDITS * GRADE
D54: Requirements Engineering | G54: 3 | H54: 17 | I54: =G54*H54 -> 51
D55: Web Design | G55: 3 | H55: 17.5 | I55: =G55*H55 -> 52.5
D56: Software Quarity Assurance | G56: 3 | H56: 17 | I56: =G56*H56 -> 51
D57: TOTAL | G57: =SUM(G54:G56) -> 9 | I57: =SUM(I54:I56) -> 154.5
D58: SEMESTER-6 | J58: =I69/G69 -> 16.911111
D62: COURSE NAME | G62: CREDITS | H62: GRADE /20 | I62: CREDITS * GRADE
...

Sheet FINAL RESULT
D8: SEMESTER-1 | J8: =I18/G18 -> 16.590625
D11: COURSE NAME | G11: CREDITS | H11: GRADE /20 | I11: CREDITS * GRADE
D12: APPLIED MATHEMATICS | G12: 3 | H12: 16.8 | I12: =G12*H12 -> 50.4
D13: INTRODUCTION TO BIBLE STUDIES | G13: 2 | H13: 17.8 | I13: =G13*H13 -> 35.6
D14: INTRODUCTION TO COMPUTER APPLICATION | G14: 3 | H14: 17.6 | I14: =G14*H14 -> 52.8
D15: PRINCIPALS OF ACCOUNTING | G15: 3 | H15: 16.55 | I15: =G15*H15 -> 49.65
D16: GENERAL ENGLISH | G16: 3 | H16: 15 | I16: =G16*H16 -> 45
D17: STUDY AND RESEARCH METHODS | G17: 2 | H17: 16 | I17: =G17*H17 -> 32
D18: TOTAL | G18: =SUM(G12:G17) -> 16 | I18: =SUM(I12:I17) -> 265.45
D19: SEMESTER-2-SUMMER | J19: =I27/G27 -> 16.066667
D23: COURSE NAME | G23: CREDITS | H23: GRADE /20 | I23: CREDITS * GRADE
D24: ='EXPECTED RESULTS'!D24 -> DBMS | G24: ='EXPECTED RESULTS'!G24 -> 3 | H24: =0.71*20 -> 14.2 | I24: =G24*H24 -> 42.6
D25: ='EXPECTED RESULTS'!D25 -> Computer Maintenance | G25: ='EXPECTED RESULTS'!G25 -> 3 | H25: =0.93*20 -> 18.6 | I25: =G25*H25 -> 55.8
D26: ='EXPECTED RESULTS'!D26 -> Digital computer Fundamentals | G26: ='EXPECTED RESULTS'!G26 -> 3 | H26: =0.77*20 -> 15.4 | I26: =G26*H26 -> 46.2
D27: TOTAL | G27: =SUM(G24:G26) -> 9 | I27: =SUM(I24:I26) -> 144.6
D28: SEMESTER-3 | J28: =I38/G38 -> 16.204444
D32: COURSE NAME | G32: CREDITS | H32: GRADE /20 | I32: CREDITS * GRADE
D33: ='EXPECTED RESULTS'!D33 -> Multvaliable Calculus and ODE | G33: ='EXPECTED RESULTS'!G33 -> 4 | H33: 11.3 | I33: =G33*H33 -> 45.2
D34: ='EXPECTED RESULTS'!D34 -> Intro to Computer Programming | G34: ='EXPECTED RESULTS'!G34 -> 4 | H34: 18.14 | I34: =G34*H34 -> 72.56
D35: ='EXPECTED RESULTS'!D35 -> Software Engineering | G35: ='EXPECTED RESULTS'!G35 -> 3 | H35: 15.5 | I35: =G35*H35 -> 46.5
D36: ='EXPECTED RESULTS'!D36 -> Descrptive Statistics | G36: ='EXPECTED RESULTS'!G36 -> 3 | H36: 17.1 | I36: =G36*H36 -> 51.3
D37: ='EXPECTED RESULTS'!D37 -> Computer Networks | G37: ='EXPECTED RESULTS'!G37 -> 4 | H37: 19.03 | I37: =G37*H37 -> 76.12
D38: TOTAL | G38: =SUM(G33:G37) -> 18 | I38: =SUM(I33:I37) -> 291.68
D39: SEMESTER-4 | J39: =I49/G49 -> 17.063158
D42: COURSE NAME | G42: CREDITS | H42: GRADE /20 | I42: CREDITS * GRADE
D43: ='EXPECTED RESULTS'!D42 -> Operating systems | G43: ='EXPECTED RESULTS'!G42 -> 4 | H43: 15.9 | I43: =G43*H43 -> 63.6
D44: ='EXPECTED RESULTS'!D43 -> Academic English Writing | G44: ='EXPECTED RESULTS'!G43 -> 3 | H44: =(85.5/100)*20 -> 17.1 | I44: =G44*H44 -> 51.3
D45: ='EXPECTED RESULTS'!D44 -> Programming with C | G45: ='EXPECTED RESULTS'!G44 -> 4 | H45: =(90.5/100)*20 -> 18.1 | I45: =G45*H45 -> 72.4
D46: ='EXPECTED RESULTS'!D45 -> Probalibility and Statistics | G46: ='EXPECTED RESULTS'!G45 -> 3 | H46: 16.7 | I46: =G46*H46 -> 50.1
D47: ='EXPECTED RESULTS'!D46 -> Software Project management | G47: ='EXPECTED RESULTS'!G46 -> 3 | H47: 16.4 | I47: =G47*H47 -> 49.2
D48: ='EXPECTED RESULTS'!D47 -> Healph Principles | G48: ='EXPECTED RESULTS'!G47 -> 2 | H48: 18.8 | I48: =G48*H48 -> 37.6
D49: TOTAL | G49: =SUM(G43:G48) -> 19 | I49: =SUM(I43:I48) -> 324.2
D50: ='EXPECTED RESULTS'!D49 -> SEMESTER-5-SUMMER | J50: =I58/G58 -> 17.933333
M52: ;
D54: COURSE NAME | G54: CREDITS | H54: GRADE /20 | I54: CREDITS * GRADE
D55: ='EXPECTED RESULTS'!D54 -> Requirements Engineering | G55: ='EXPECTED RESULTS'!G54 -> 3 | H55: =(88.5/100)*20 -> 17.7 | I55: =G55*H55 -> 53.1
D56: ='EXPECTED RESULTS'!D55 -> Web Design | G56: ='EXPECTED RESULTS'!G55 -> 3 | H56: =(84/100)*20 -> 16.8 | I56: =G56*H56 -> 50.4
D57: ='EXPECTED RESULTS'!D56 -> Software Quarity Assurance | G57: ='EXPECTED RESULTS'!G56 -> 3 | H57: =(96.5/100)*20 -> 19.3 | I57: =G57*H57 -> 57.9
D58: TOTAL | G58: =SUM(G55:G57) -> 9 | I58: =SUM(I55:I57) -> 161.4
D59: SEMESTER-6 | J59: =I70/G70 -> 0
...

Sheet COURSES
A1: Academic English Writing
A2: Applied Mathematics
A3: Bible Doctrines
A4: Best Programming Practice & Design Patterns
A5: Computer Maintenance
A6: Computer Networks
A7: Data Structures and Algorithms
A8: Database Development with PL/SQL
A9: Database Management Systems
A10: Descriptive Statistics
A11: Digital Computer Fundamentals
A12: Dot Net
... A45: Zero Credits

Sheet Major gpa and General gpa 
A1: MAJOR GPA AND GENERAL GPA WITH OVERALL GPA SO FAR
A7: MAJOR COURSES | H7: GENERAL COURSES
A8: C.NAME | D8: CR | E8: GRD/20 | F8: CR*GRD | H8: C.NAME | K8: CR | L8: GRD/20 | M8: CR*GRD
A9: APPLIED MATH | D9: 3 | E9: 16.8 | F9: =D9*E9 -> 50.4 | H9: Study and research | K9: 2 | L9: 16 | M9: =K9*L9 -> 32
A10: Compute Maintenance | D10: 3 | E10: 18.66 | F10: =D10*E10 -> 55.98 | H10: General English | K10: 3 | L10: 15 | M10: =K10*L10 -> 45
A11: DBMS | D11: 3 | E11: 14.55 | F11: =D11*E11 -> 43.65 | H11: Intro to Computer application | K11: 3 | L11: 17.6 | M11: =K11*L11 -> 52.8
A12: DCF | D12: 3 | E12: 15.4 | F12: =D12*E12 -> 46.2 | H12: Intro to bible study | K12: 2 | L12: 17.8 | M12: =K12*L12 -> 35.6
A13: ICP | D13: 4 | E13: 18.14 | F13: =D13*E13 -> 72.56 | H13: Principle of Accounting I | K13: 3 | L13: 16.55 | M13: =K13*L13 -> 49.65
A14: CNets | D14: 4 | E14: 19.03 | F14: =D14*E14 -> 76.12 | H14: Descriptive statistics | K14: 3 | L14: 17.1 | M14: =K14*L14 -> 51.3
A15: Multivariable | D15: 4 | E15: 11.3 | F15: =D15*E15 -> 45.2 | H15: Health Principles | K15: 2 | L15: 18.8 | M15: =K15*L15 -> 37.6
A16: Software Engineering | D16: 3 | E16: 15.5 | F16: =D16*E16 -> 46.5 | H16: Academic Engrish Writing | K16: 3 | L16: 17.1 | M16: =K16*L16 -> 51.3
A17: OS | D17: 4 | E17: 15.9 | F17: =D17*E17 -> 63.6 | H17: Bible Docrines | M17: =K17*L17 -> 0
A18: Programming with C | D18: 4 | E18: 18.1 | F18: =D18*E18 -> 72.4 | H18: Philosophy and Religion | M18: =K18*L18 -> 0
A19: SPM | D19: 3 | E19: 16.4 | F19: =D19*E19 -> 49.2
A20: ProbabilIty | D20: 3 | E20: 16.7 | F20: =D20*E20 -> 50.1
A21: Web Design | D21: 3 | E21: =(84/100)*20 -> 16.8 | F21: =D21*E21 -> 50.4
A22: Requirements Engineering | D22: 3 | E22: =(96.5/100)*20 -> 19.3 | F22: =D22*E22 -> 57.9
A23: Software Quality Assurance | D23: 3 | E23: =(88.5/100)*20 -> 17.7 | F23: =D23*E23 -> 53.1
A24: DB Development with PL/SQL | F24: =D24*E24 -> 0
A25: Object Oriented programming | F25: =D25*E25 -> 0
A26: Bible doctrines | F26: =D26*E26 -> 0
A27: English Proficiency I | F27: =D27*E27 -> 0
A28: Introduction to linux | F28: =D28*E28 -> 0
A29: Intro to big data | F29: =D29*E29 -> 0
A30: English Proficiency II | F30: =D30*E30 -> 0
A31: Java Programming | F31: =D31*E31 -> 0
A32: IMS | F32: =D32*E32 -> 0
A33: Dot Net | F33: =D33*E33 -> 0
A34: Intrepreneurship | F34: =D34*E34 -> 0
A35: Software Modeling Design | F35: =D35*E35 -> 0
... A45: Final Year Project | F45: =D45*E45 -> 0
A46: TOTAL | D46: =SUM(D9:D45) -> 50 | F46: =SUM(F9:F45) -> 833.31 | H46: TOTAL | K46: =SUM(K9:K16) -> 21 | M46: =SUM(M9:M16) -> 355.25
A48: Major GPA | D48: =F46/D46 -> 16.6662 | H48: General GPA | K48: =M46/K46 -> 16.916667
A50: OVERALL GPA | H50: =SUM(M46,F46)/SUM(K46,D46) -> 16.740282
